2025-06-16 04:48:33,361 INFO: DnD Monster Data startup [in /app/app.py:29]
2025-06-16 05:02:26,918 INFO: DnD Monster Data startup [in /app/app.py:29]
2025-06-19 06:50:00,039 INFO: DnD Monster Data startup [in /app/app.py:29]
2025-06-19 06:51:58,068 INFO: DnD Monster Data startup [in /app/app.py:29]
2025-06-19 07:15:36,485 INFO: DnD Monster Data startup [in /app/app.py:29]
2025-06-19 22:55:07,416 INFO: DnD Monster Data startup [in /app/app.py:30]
2025-06-19 22:55:08,468 INFO: MongoDB connection established successfully [in /app/app.py:65]
2025-06-19 22:57:23,650 INFO: DnD Monster Data startup [in /app/app.py:30]
2025-06-19 22:57:24,184 INFO: MongoDB connection established successfully [in /app/app.py:65]
2025-06-19 23:00:24,969 INFO: DnD Monster Data startup [in /app/app.py:30]
2025-06-19 23:00:29,980 ERROR: Failed to connect to MongoDB: mongo:27017: [Errno 111] Connection refused (configured timeouts: socketTimeoutMS: 20000.0ms, connectTimeoutMS: 20000.0ms), Timeout: 5.0s, Topology Description: <TopologyDescription id: 685496884ab54d92eda4ac07, topology_type: Unknown, servers: [<ServerDescription ('mongo', 27017) server_type: Unknown, rtt: None, error=AutoReconnect('mongo:27017: [Errno 111] Connection refused (configured timeouts: socketTimeoutMS: 20000.0ms, connectTimeoutMS: 20000.0ms)')>]> [in /app/app.py:52]
2025-06-19 23:00:29,981 ERROR: Initial MongoDB connection failed: mongo:27017: [Errno 111] Connection refused (configured timeouts: socketTimeoutMS: 20000.0ms, connectTimeoutMS: 20000.0ms), Timeout: 5.0s, Topology Description: <TopologyDescription id: 685496884ab54d92eda4ac07, topology_type: Unknown, servers: [<ServerDescription ('mongo', 27017) server_type: Unknown, rtt: None, error=AutoReconnect('mongo:27017: [Errno 111] Connection refused (configured timeouts: socketTimeoutMS: 20000.0ms, connectTimeoutMS: 20000.0ms)')>]> [in /app/app.py:67]
2025-06-19 23:00:40,595 ERROR: Exception on / [GET] [in /usr/local/lib/python3.11/site-packages/flask/app.py:875]
Traceback (most recent call last):
  File "/usr/local/lib/python3.11/site-packages/flask/app.py", line 1511, in wsgi_app
    response = self.full_dispatch_request()
               ^^^^^^^^^^^^^^^^^^^^^^^^^^^^
  File "/usr/local/lib/python3.11/site-packages/flask/app.py", line 919, in full_dispatch_request
    rv = self.handle_user_exception(e)
         ^^^^^^^^^^^^^^^^^^^^^^^^^^^^^
  File "/usr/local/lib/python3.11/site-packages/flask/app.py", line 917, in full_dispatch_request
    rv = self.dispatch_request()
         ^^^^^^^^^^^^^^^^^^^^^^^
  File "/usr/local/lib/python3.11/site-packages/flask/app.py", line 902, in dispatch_request
    return self.ensure_sync(self.view_functions[rule.endpoint])(**view_args)  # type: ignore[no-any-return]
           ^^^^^^^^^^^^^^^^^^^^^^^^^^^^^^^^^^^^^^^^^^^^^^^^^^^^^^^^^^^^^^^^^
  File "/app/app.py", line 77, in index
    flash("Database connection error. Please check the logs.", "error")
  File "/usr/local/lib/python3.11/site-packages/flask/helpers.py", line 335, in flash
    session["_flashes"] = flashes
    ~~~~~~~^^^^^^^^^^^^
  File "/usr/local/lib/python3.11/site-packages/flask/sessions.py", line 104, in _fail
    raise RuntimeError(
RuntimeError: The session is unavailable because no secret key was set.  Set the secret_key on the application to something unique and secret.
2025-06-19 23:00:42,094 ERROR: Exception on / [GET] [in /usr/local/lib/python3.11/site-packages/flask/app.py:875]
Traceback (most recent call last):
  File "/usr/local/lib/python3.11/site-packages/flask/app.py", line 1511, in wsgi_app
    response = self.full_dispatch_request()
               ^^^^^^^^^^^^^^^^^^^^^^^^^^^^
  File "/usr/local/lib/python3.11/site-packages/flask/app.py", line 919, in full_dispatch_request
    rv = self.handle_user_exception(e)
         ^^^^^^^^^^^^^^^^^^^^^^^^^^^^^
  File "/usr/local/lib/python3.11/site-packages/flask/app.py", line 917, in full_dispatch_request
    rv = self.dispatch_request()
         ^^^^^^^^^^^^^^^^^^^^^^^
  File "/usr/local/lib/python3.11/site-packages/flask/app.py", line 902, in dispatch_request
    return self.ensure_sync(self.view_functions[rule.endpoint])(**view_args)  # type: ignore[no-any-return]
           ^^^^^^^^^^^^^^^^^^^^^^^^^^^^^^^^^^^^^^^^^^^^^^^^^^^^^^^^^^^^^^^^^
  File "/app/app.py", line 77, in index
    flash("Database connection error. Please check the logs.", "error")
  File "/usr/local/lib/python3.11/site-packages/flask/helpers.py", line 335, in flash
    session["_flashes"] = flashes
    ~~~~~~~^^^^^^^^^^^^
  File "/usr/local/lib/python3.11/site-packages/flask/sessions.py", line 104, in _fail
    raise RuntimeError(
RuntimeError: The session is unavailable because no secret key was set.  Set the secret_key on the application to something unique and secret.
2025-06-19 23:06:58,258 ERROR: Exception on / [GET] [in /usr/local/lib/python3.11/site-packages/flask/app.py:875]
Traceback (most recent call last):
  File "/usr/local/lib/python3.11/site-packages/flask/app.py", line 1511, in wsgi_app
    response = self.full_dispatch_request()
               ^^^^^^^^^^^^^^^^^^^^^^^^^^^^
  File "/usr/local/lib/python3.11/site-packages/flask/app.py", line 919, in full_dispatch_request
    rv = self.handle_user_exception(e)
         ^^^^^^^^^^^^^^^^^^^^^^^^^^^^^
  File "/usr/local/lib/python3.11/site-packages/flask/app.py", line 917, in full_dispatch_request
    rv = self.dispatch_request()
         ^^^^^^^^^^^^^^^^^^^^^^^
  File "/usr/local/lib/python3.11/site-packages/flask/app.py", line 902, in dispatch_request
    return self.ensure_sync(self.view_functions[rule.endpoint])(**view_args)  # type: ignore[no-any-return]
           ^^^^^^^^^^^^^^^^^^^^^^^^^^^^^^^^^^^^^^^^^^^^^^^^^^^^^^^^^^^^^^^^^
  File "/app/app.py", line 77, in index
    flash("Database connection error. Please check the logs.", "error")
  File "/usr/local/lib/python3.11/site-packages/flask/helpers.py", line 335, in flash
    session["_flashes"] = flashes
    ~~~~~~~^^^^^^^^^^^^
  File "/usr/local/lib/python3.11/site-packages/flask/sessions.py", line 104, in _fail
    raise RuntimeError(
RuntimeError: The session is unavailable because no secret key was set.  Set the secret_key on the application to something unique and secret.
2025-06-19 23:17:20,926 ERROR: Exception on / [GET] [in /usr/local/lib/python3.11/site-packages/flask/app.py:875]
Traceback (most recent call last):
  File "/usr/local/lib/python3.11/site-packages/flask/app.py", line 1511, in wsgi_app
    response = self.full_dispatch_request()
               ^^^^^^^^^^^^^^^^^^^^^^^^^^^^
  File "/usr/local/lib/python3.11/site-packages/flask/app.py", line 919, in full_dispatch_request
    rv = self.handle_user_exception(e)
         ^^^^^^^^^^^^^^^^^^^^^^^^^^^^^
  File "/usr/local/lib/python3.11/site-packages/flask/app.py", line 917, in full_dispatch_request
    rv = self.dispatch_request()
         ^^^^^^^^^^^^^^^^^^^^^^^
  File "/usr/local/lib/python3.11/site-packages/flask/app.py", line 902, in dispatch_request
    return self.ensure_sync(self.view_functions[rule.endpoint])(**view_args)  # type: ignore[no-any-return]
           ^^^^^^^^^^^^^^^^^^^^^^^^^^^^^^^^^^^^^^^^^^^^^^^^^^^^^^^^^^^^^^^^^
  File "/app/app.py", line 77, in index
    flash("Database connection error. Please check the logs.", "error")
  File "/usr/local/lib/python3.11/site-packages/flask/helpers.py", line 335, in flash
    session["_flashes"] = flashes
    ~~~~~~~^^^^^^^^^^^^
  File "/usr/local/lib/python3.11/site-packages/flask/sessions.py", line 104, in _fail
    raise RuntimeError(
RuntimeError: The session is unavailable because no secret key was set.  Set the secret_key on the application to something unique and secret.
2025-06-19 23:23:21,172 INFO: DnD Monster Data startup [in /app/app.py:30]
2025-06-19 23:23:21,707 INFO: MongoDB connection established successfully [in /app/app.py:65]
2025-06-26 19:39:48,905 INFO: DnD Monster Data startup [in /app/app.py:30]
2025-06-26 19:39:49,965 INFO: MongoDB connection established successfully [in /app/app.py:65]
2025-06-26 19:41:59,127 INFO: DnD Monster Data startup [in /app/app.py:30]
2025-06-26 19:42:00,167 INFO: MongoDB connection established successfully [in /app/app.py:65]
2025-06-26 19:43:04,130 INFO: DnD Monster Data startup [in /app/app.py:30]
2025-06-26 19:43:09,219 ERROR: Failed to connect to MongoDB: mongo:27017: [Errno 111] Connection refused (configured timeouts: socketTimeoutMS: 20000.0ms, connectTimeoutMS: 20000.0ms), Timeout: 5.0s, Topology Description: <TopologyDescription id: 685da2c83e789dd6f7d309bc, topology_type: Unknown, servers: [<ServerDescription ('mongo', 27017) server_type: Unknown, rtt: None, error=AutoReconnect('mongo:27017: [Errno 111] Connection refused (configured timeouts: socketTimeoutMS: 20000.0ms, connectTimeoutMS: 20000.0ms)')>]> [in /app/app.py:52]
2025-06-26 19:43:09,220 ERROR: Initial MongoDB connection failed: mongo:27017: [Errno 111] Connection refused (configured timeouts: socketTimeoutMS: 20000.0ms, connectTimeoutMS: 20000.0ms), Timeout: 5.0s, Topology Description: <TopologyDescription id: 685da2c83e789dd6f7d309bc, topology_type: Unknown, servers: [<ServerDescription ('mongo', 27017) server_type: Unknown, rtt: None, error=AutoReconnect('mongo:27017: [Errno 111] Connection refused (configured timeouts: socketTimeoutMS: 20000.0ms, connectTimeoutMS: 20000.0ms)')>]> [in /app/app.py:67]
2025-06-26 19:59:58,912 INFO: DnD Monster Data startup [in /app/app.py:30]
2025-06-26 20:00:03,446 INFO: MongoDB connection established successfully [in /app/app.py:65]
2025-06-26 20:13:10,563 INFO: DnD Monster Data startup [in /app/app.py:30]
2025-06-26 20:13:15,585 INFO: MongoDB connection established successfully [in /app/app.py:65]
2025-06-26 20:14:33,849 INFO: DnD Monster Data startup [in /app/app.py:30]
2025-06-26 20:14:38,374 INFO: MongoDB connection established successfully [in /app/app.py:65]
